Workbook

Sheet fact_events
A1: event_id | B1: store_id | C1: campaign_id | D1: product_code | E1: base_price | F1: promo_type | G1: quantity_sold(before_promo) | H1: quantity_sold(after_promo) | I1: Campaign_Name | J1: Promo Impact (%) | K1: Sales Amount | L1: City
A2: 7f650b | B2: STCBE-2 | C2: CAMP_SAN_01 | D2: P11 | E2: 190 | F2: 50% OFF | G2: 34 | H2: 52 | I2: =_xlfn.XLOOKUP($C2,dim_campaigns!$D$2:$D$3,dim_campaigns!$A$2:$A$3,"",0) -> Sankranti | J2: =IFERROR((H2-G2)/G2,0) -> 0.52941176 | K2: =E2*G2+(E2-IF(F2="500 Cashback",500,IF(F2="BOGOF",E2*50%,IF(F2="25% OFF",E2*25%,IF(F2="33% OFF",E2*33%,IF(F2="50% OFF",E2*50%,0))))))*H2 -> 11400 | L2: =VLOOKUP($B2,dim_stores!$A$1:$C$51,2,0) -> Coimbatore
A3: a21f91 | B3: STBLR-8 | C3: CAMP_DIW_01 | D3: P03 | E3: 156 | F3: 25% OFF | G3: 393 | H3: 322 | I3: =_xlfn.XLOOKUP($C3,dim_campaigns!$D$2:$D$3,dim_campaigns!$A$2:$A$3,"",0) -> Diwali | J3: =IFERROR((H3-G3)/G3,0) -> -0.18066158 | K3: =E3*G3+(E3-IF(F3="500 Cashback",500,IF(F3="BOGOF",E3*50%,IF(F3="25% OFF",E3*25%,IF(F3="33% OFF",E3*33%,IF(F3="50% OFF",E3*50%,0))))))*H3 -> 98982 | L3: =VLOOKUP($B3,dim_stores!$A$1:$C$51,2,0) -> Bengaluru
A4: 78bc80 | B4: STVJD-0 | C4: CAMP_SAN_01 | D4: P07 | E4: 300 | F4: BOGOF | G4: 22 | H4: 85 | I4: =_xlfn.XLOOKUP($C4,dim_campaigns!$D$2:$D$3,dim_campaigns!$A$2:$A$3,"",0) -> Sankranti | J4: =IFERROR((H4-G4)/G4,0) -> 2.8636364 | K4: =E4*G4+(E4-IF(F4="500 Cashback",500,IF(F4="BOGOF",E4*50%,IF(F4="25% OFF",E4*25%,IF(F4="33% OFF",E4*33%,IF(F4="50% OFF",E4*50%,0))))))*H4 -> 19350 | L4: =VLOOKUP($B4,dim_stores!$A$1:$C$51,2,0) -> Vijayawada
A5: a1503f | B5: STCBE-1 | C5: CAMP_DIW_01 | D5: P15 | E5: 3000 | F5: 500 Cashback | G5: 329 | H5: 1000 | I5: =_xlfn.XLOOKUP($C5,dim_campaigns!$D$2:$D$3,dim_campaigns!$A$2:$A$3,"",0) -> Diwali | J5: =IFERROR((H5-G5)/G5,0) -> 2.0395137 | K5: =E5*G5+(E5-IF(F5="500 Cashback",500,IF(F5="BOGOF",E5*50%,IF(F5="25% OFF",E5*25%,IF(F5="33% OFF",E5*33%,IF(F5="50% OFF",E5*50%,0))))))*H5 -> 3487000 | L5: =VLOOKUP($B5,dim_stores!$A$1:$C$51,2,0) -> Coimbatore
A6: 1091cf | B6: STBLR-6 | C6: CAMP_DIW_01 | D6: P05 | E6: 55 | F6: 25% OFF | G6: 108 | H6: 93 | I6: =_xlfn.XLOOKUP($C6,dim_campaigns!$D$2:$D$3,dim_campaigns!$A$2:$A$3,"",0) -> Diwali | J6: =IFERROR((H6-G6)/G6,0) -> -0.13888889 | K6: =E6*G6+(E6-IF(F6="500 Cashback",500,IF(F6="BOGOF",E6*50%,IF(F6="25% OFF",E6*25%,IF(F6="33% OFF",E6*33%,IF(F6="50% OFF",E6*50%,0))))))*H6 -> 9776.25 | L6: =VLOOKUP($B6,dim_stores!$A$1:$C$51,2,0) -> Bengaluru
A7: 8.02e+96 | B7: STBLR-4 | C7: CAMP_DIW_01 | D7: P11 | E7: 190 | F7: 50% OFF | G7: 91 | H7: 116 | I7: =_xlfn.XLOOKUP($C7,dim_campaigns!$D$2:$D$3,dim_campaigns!$A$2:$A$3,"",0) -> Diwali | J7: =IFERROR((H7-G7)/G7,0) -> 0.27472527 | K7: =E7*G7+(E7-IF(F7="500 Cashback",500,IF(F7="BOGOF",E7*50%,IF(F7="25% OFF",E7*25%,IF(F7="33% OFF",E7*33%,IF(F7="50% OFF",E7*50%,0))))))*H7 -> 28310 | L7: =VLOOKUP($B7,dim_stores!$A$1:$C$51,2,0) -> Bengaluru
A8: 73d86f | B8: STVSK-2 | C8: CAMP_SAN_01 | D8: P10 | E8: 50 | F8: 25% OFF | G8: 31 | H8: 26 | I8: =_xlfn.XLOOKUP($C8,dim_campaigns!$D$2:$D$3,dim_campaigns!$A$2:$A$3,"",0) -> Sankranti | J8: =IFERROR((H8-G8)/G8,0) -> -0.16129032 | K8: =E8*G8+(E8-IF(F8="500 Cashback",500,IF(F8="BOGOF",E8*50%,IF(F8="25% OFF",E8*25%,IF(F8="33% OFF",E8*33%,IF(F8="50% OFF",E8*50%,0))))))*H8 -> 2525 | L8: =VLOOKUP($B8,dim_stores!$A$1:$C$51,2,0) -> Visakhapatnam
A9: fe3560 | B9: STHYD-4 | C9: CAMP_DIW_01 | D9: P13 | E9: 350 | F9: BOGOF | G9: 73 | H9: 245 | I9: =_xlfn.XLOOKUP($C9,dim_campaigns!$D$2:$D$3,dim_campaigns!$A$2:$A$3,"",0) -> Diwali | J9: =IFERROR((H9-G9)/G9,0) -> 2.3561644 | K9: =E9*G9+(E9-IF(F9="500 Cashback",500,IF(F9="BOGOF",E9*50%,IF(F9="25% OFF",E9*25%,IF(F9="33% OFF",E9*33%,IF(F9="50% OFF",E9*50%,0))))))*H9 -> 68425 | L9: =VLOOKUP($B9,dim_stores!$A$1:$C$51,2,0) -> Hyderabad
A10: 6b2afc | B10: STCBE-4 | C10: CAMP_SAN_01 | D10: P08 | E10: 1190 | F10: BOGOF | G10: 30 | H10: 79 | I10: =_xlfn.XLOOKUP($C10,dim_campaigns!$D$2:$D$3,dim_campaigns!$A$2:$A$3,"",0) -> Sankranti | J10: =IFERROR((H10-G10)/G10,0) -> 1.6333333 | K10: =E10*G10+(E10-IF(F10="500 Cashback",500,IF(F10="BOGOF",E10*50%,IF(F10="25% OFF",E10*25%,IF(F10="33% OFF",E10*33%,IF(F10="50% OFF",E10*50%,0))))))*H10 -> 82705 | L10: =VLOOKUP($B10,dim_stores!$A$1:$C$51,2,0) -> Coimbatore
A11: ce5851 | B11: STMDU-2 | C11: CAMP_SAN_01 | D11: P03 | E11: 200 | F11: BOGOF | G11: 318 | H11: 1265 | I11: =_xlfn.XLOOKUP($C11,dim_campaigns!$D$2:$D$3,dim_campaigns!$A$2:$A$3,"",0) -> Sankranti | J11: =IFERROR((H11-G11)/G11,0) -> 2.9779874 | K11: =E11*G11+(E11-IF(F11="500 Cashback",500,IF(F11="BOGOF",E11*50%,IF(F11="25% OFF",E11*25%,IF(F11="33% OFF",E11*33%,IF(F11="50% OFF",E11*50%,0))))))*H11 -> 190100 | L11: =VLOOKUP($B11,dim_stores!$A$1:$C$51,2,0) -> Madurai
A12: dd6685 | B12: STMYS-2 | C12: CAMP_DIW_01 | D12: P06 | E12: 415 | F12: 25% OFF | G12: 78 | H12: 70 | I12: =_xlfn.XLOOKUP($C12,dim_campaigns!$D$2:$D$3,dim_campaigns!$A$2:$A$3,"",0) -> Diwali | J12: =IFERROR((H12-G12)/G12,0) -> -0.1025641 | K12: =E12*G12+(E12-IF(F12="500 Cashback",500,IF(F12="BOGOF",E12*50%,IF(F12="25% OFF",E12*25%,IF(F12="33% OFF",E12*33%,IF(F12="50% OFF",E12*50%,0))))))*H12 -> 54157.5 | L12: =VLOOKUP($B12,dim_stores!$A$1:$C$51,2,0) -> Mysuru
A13: 8f25a6 | B13: STHYD-6 | C13: CAMP_SAN_01 | D13: P15 | E13: 3000 | F13: 500 Cashback | G13: 126 | H13: 302 | I13: =_xlfn.XLOOKUP($C13,dim_campaigns!$D$2:$D$3,dim_campaigns!$A$2:$A$3,"",0) -> Sankranti | J13: =IFERROR((H13-G13)/G13,0) -> 1.3968254 | K13: =E13*G13+(E13-IF(F13="500 Cashback",500,IF(F13="BOGOF",E13*50%,IF(F13="25% OFF",E13*25%,IF(F13="33% OFF",E13*33%,IF(F13="50% OFF",E13*50%,0))))))*H13 -> 1133000 | L13: =VLOOKUP($B13,dim_stores!$A$1:$C$51,2,0) -> Hyderabad
A14: 5c3c33 | B14: STCHE-6 | C14: CAMP_DIW_01 | D14: P12 | E14: 62 | F14: 50% OFF | G14: 154 | H14: 207 | I14: =_xlfn.XLOOKUP($C14,dim_campaigns!$D$2:$D$3,dim_campaigns!$A$2:$A$3,"",0) -> Diwali | J14: =IFERROR((H14-G14)/G14,0) -> 0.34415584 | K14: =E14*G14+(E14-IF(F14="500 Cashback",500,IF(F14="BOGOF",E14*50%,IF(F14="25% OFF",E14*25%,IF(F14="33% OFF",E14*33%,IF(F14="50% OFF",E14*50%,0))))))*H14 -> 15965 | L14: =VLOOKUP($B14,dim_stores!$A$1:$C$51,2,0) -> Chennai
A15: d290a1 | B15: STBLR-3 | C15: CAMP_DIW_01 | D15: P04 | E15: 290 | F15: 25% OFF | G15: 343 | H15: 270 | I15: =_xlfn.XLOOKUP($C15,dim_campaigns!$D$2:$D$3,dim_campaigns!$A$2:$A$3,"",0) -> Diwali | J15: =IFERROR((H15-G15)/G15,0) -> -0.21282799 | K15: =E15*G15+(E15-IF(F15="500 Cashback",500,IF(F15="BOGOF",E15*50%,IF(F15="25% OFF",E15*25%,IF(F15="33% OFF",E15*33%,IF(F15="50% OFF",E15*50%,0))))))*H15 -> 158195 | L15: =VLOOKUP($B15,dim_stores!$A$1:$C$51,2,0) -> Bengaluru
A16: 635862 | B16: STVSK-4 | C16: CAMP_SAN_01 | D16: P02 | E16: 860 | F16: 33% OFF | G16: 348 | H16: 480 | I16: =_xlfn.XLOOKUP($C16,dim_campaigns!$D$2:$D$3,dim_campaigns!$A$2:$A$3,"",0) -> Sankranti | J16: =IFERROR((H16-G16)/G16,0) -> 0.37931034 | K16: =E16*G16+(E16-IF(F16="500 Cashback",500,IF(F16="BOGOF",E16*50%,IF(F16="25% OFF",E16*25%,IF(F16="33% OFF",E16*33%,IF(F16="50% OFF",E16*50%,0))))))*H16 -> 575856 | L16: =VLOOKUP($B16,dim_stores!$A$1:$C$51,2,0) -> Visakhapatnam
A17: c0ecb5 | B17: STCHE-2 | C17: CAMP_SAN_01 | D17: P07 | E17: 300 | F17: BOGOF | G17: 43 | H17: 167 | I17: =_xlfn.XLOOKUP($C17,dim_campaigns!$D$2:$D$3,dim_campaigns!$A$2:$A$3,"",0) -> Sankranti | J17: =IFERROR((H17-G17)/G17,0) -> 2.8837209 | K17: =E17*G17+(E17-IF(F17="500 Cashback",500,IF(F17="BOGOF",E17*50%,IF(F17="25% OFF",E17*25%,IF(F17="33% OFF",E17*33%,IF(F17="50% OFF",E17*50%,0))))))*H17 -> 37950 | L17: =VLOOKUP($B17,dim_stores!$A$1:$C$51,2,0) -> Chennai
A18: 182caa | B18: STCHE-5 | C18: CAMP_SAN_01 | D18: P06 | E18: 415 | F18: 25% OFF | G18: 39 | H18: 33 | I18: =_xlfn.XLOOKUP($C18,dim_campaigns!$D$2:$D$3,dim_campaigns!$A$2:$A$3,"",0) -> Sankranti | J18: =IFERROR((H18-G18)/G18,0) -> -0.15384615 | K18: =E18*G18+(E18-IF(F18="500 Cashback",500,IF(F18="BOGOF",E18*50%,IF(F18="25% OFF",E18*25%,IF(F18="33% OFF",E18*33%,IF(F18="50% OFF",E18*50%,0))))))*H18 -> 26456.25 | L18: =VLOOKUP($B18,dim_stores!$A$1:$C$51,2,0) -> Chennai
A19: c4db5b | B19: STTRV-0 | C19: CAMP_DIW_01 | D19: P01 | E19: 172 | F19: 33% OFF | G19: 164 | H19: 236 | I19: =_xlfn.XLOOKUP($C19,dim_campaigns!$D$2:$D$3,dim_campaigns!$A$2:$A$3,"",0) -> Diwali | J19: =IFERROR((H19-G19)/G19,0) -> 0.43902439 | K19: =E19*G19+(E19-IF(F19="500 Cashback",500,IF(F19="BOGOF",E19*50%,IF(F19="25% OFF",E19*25%,IF(F19="33% OFF",E19*33%,IF(F19="50% OFF",E19*50%,0))))))*H19 -> 55404.64 | L19: =VLOOKUP($B19,dim_stores!$A$1:$C$51,2,0) -> Trivandrum
A20: 94f48c | B20: STVSK-1 | C20: CAMP_SAN_01 | D20: P06 | E20: 415 | F20: 25% OFF | G20: 22 | H20: 16 | I20: =_xlfn.XLOOKUP($C20,dim_campaigns!$D$2:$D$3,dim_campaigns!$A$2:$A$3,"",0) -> Sankranti | J20: =IFERROR((H20-G20)/G20,0) -> -0.27272727 | K20: =E20*G20+(E20-IF(F20="500 Cashback",500,IF(F20="BOGOF",E20*50%,IF(F20="25% OFF",E20*25%,IF(F20="33% OFF",E20*33%,IF(F20="50% OFF",E20*50%,0))))))*H20 -> 14110 | L20: =VLOOKUP($B20,dim_stores!$A$1:$C$51,2,0) -> Visakhapatnam
A21: 7ef92f | B21: STHYD-5 | C21: CAMP_SAN_01 | D21: P07 | E21: 300 | F21: BOGOF | G21: 55 | H21: 213 | I21: =_xlfn.XLOOKUP($C21,dim_campaigns!$D$2:$D$3,dim_campaigns!$A$2:$A$3,"",0) -> Sankranti | J21: =IFERROR((H21-G21)/G21,0) -> 2.8727273 | K21: =E21*G21+(E21-IF(F21="500 Cashback",500,IF(F21="BOGOF",E21*50%,IF(F21="25% OFF",E21*25%,IF(F21="33% OFF",E21*33%,IF(F21="50% OFF",E21*50%,0))))))*H21 -> 48450 | L21: =VLOOKUP($B21,dim_stores!$A$1:$C$51,2,0) -> Hyderabad
A22: 0f422c | B22: STBLR-0 | C22: CAMP_DIW_01 | D22: P14 | E22: 1020 | F22: BOGOF | G22: 42 | H22: 168 | I22: =_xlfn.XLOOKUP($C22,dim_campaigns!$D$2:$D$3,dim_campaigns!$A$2:$A$3,"",0) -> Diwali | J22: =IFERROR((H22-G22)/G22,0) -> 3 | K22: =E22*G22+(E22-IF(F22="500 Cashback",500,IF(F22="BOGOF",E22*50%,IF(F22="25% OFF",E22*25%,IF(F22="33% OFF",E22*33%,IF(F22="50% OFF",E22*50%,0))))))*H22 -> 128520 | L22: =VLOOKUP($B22,dim_stores!$A$1:$C$51,2,0) -> Bengaluru
A23: 1e9a06 | B23: STCHE-4 | C23: CAMP_DIW_01 | D23: P13 | E23: 350 | F23: BOGOF | G23: 84 | H23: 338 | I23: =_xlfn.XLOOKUP($C23,dim_campaigns!$D$2:$D$3,dim_campaigns!$A$2:$A$3,"",0) -> Diwali | J23: =IFERROR((H23-G23)/G23,0) -> 3.0238095 | K23: =E23*G23+(E23-IF(F23="500 Cashback",500,IF(F23="BOGOF",E23*50%,IF(F23="25% OFF",E23*25%,IF(F23="33% OFF",E23*33%,IF(F23="50% OFF",E23*50%,0))))))*H23 -> 88550 | L23: =VLOOKUP($B23,dim_stores!$A$1:$C$51,2,0) -> Chennai
A24: 02ebe9 | B24: STBLR-8 | C24: CAMP_DIW_01 | D24: P11 | E24: 190 | F24: 50% OFF | G24: 66 | H24: 88 | I24: =_xlfn.XLOOKUP($C24,dim_campaigns!$D$2:$D$3,dim_campaigns!$A$2:$A$3,"",0) -> Diwali | J24: =IFERROR((H24-G24)/G24,0) -> 0.33333333 | K24: =E24*G24+(E24-IF(F24="500 Cashback",500,IF(F24="BOGOF",E24*50%,IF(F24="25% OFF",E24*25%,IF(F24="33% OFF",E24*33%,IF(F24="50% OFF",E24*50%,0))))))*H24 -> 20900 | L24: =VLOOKUP($B24,dim_stores!$A$1:$C$51,2,0) -> Bengaluru
A25: 260ff2 | B25: STMYS-2 | C25: CAMP_SAN_01 | D25: P01 | E25: 172 | F25: 33% OFF | G25: 204 | H25: 291 | I25: =_xlfn.XLOOKUP($C25,dim_campaigns!$D$2:$D$3,dim_campaigns!$A$2:$A$3,"",0) -> Sankranti | J25: =IFERROR((H25-G25)/G25,0) -> 0.42647059 | K25: =E25*G25+(E25-IF(F25="500 Cashback",500,IF(F25="BOGOF",E25*50%,IF(F25="25% OFF",E25*25%,IF(F25="33% OFF",E25*33%,IF(F25="50% OFF",E25*50%,0))))))*H25 -> 68622.84 | L25: =VLOOKUP($B25,dim_stores!$A$1:$C$51,2,0) -> Mysuru
A26: 7fc923 | B26: STTRV-0 | C26: CAMP_SAN_01 | D26: P08 | E26: 1190 | F26: BOGOF | G26: 19 | H26: 74 | I26: =_xlfn.XLOOKUP($C26,dim_campaigns!$D$2:$D$3,dim_campaigns!$A$2:$A$3,"",0) -> Sankranti | J26: =IFERROR((H26-G26)/G26,0) -> 2.8947368 | K26: =E26*G26+(E26-IF(F26="500 Cashback",500,IF(F26="BOGOF",E26*50%,IF(F26="25% OFF",E26*25%,IF(F26="33% OFF",E26*33%,IF(F26="50% OFF",E26*50%,0))))))*H26 -> 66640 | L26: =VLOOKUP($B26,dim_stores!$A$1:$C$51,2,0) -> Trivandrum
A27: b08c12 | B27: STMDU-3 | C27: CAMP_DIW_01 | D27: P03 | E27: 156 | F27: 25% OFF | G27: 227 | H27: 202 | I27: =_xlfn.XLOOKUP($C27,dim_campaigns!$D$2:$D$3,dim_campaigns!$A$2:$A$3,"",0) -> Diwali | J27: =IFERROR((H27-G27)/G27,0) -> -0.11013216 | K27: =E27*G27+(E27-IF(F27="500 Cashback",500,IF(F27="BOGOF",E27*50%,IF(F27="25% OFF",E27*25%,IF(F27="33% OFF",E27*33%,IF(F27="50% OFF",E27*50%,0))))))*H27 -> 59046 | L27: =VLOOKUP($B27,dim_stores!$A$1:$C$51,2,0) -> Madurai
A28: ca7298 | B28: STCBE-2 | C28: CAMP_SAN_01 | D28: P15 | E28: 3000 | F28: 500 Cashback | G28: 85 | H28: 228 | I28: =_xlfn.XLOOKUP($C28,dim_campaigns!$D$2:$D$3,dim_campaigns!$A$2:$A$3,"",0) -> Sankranti | J28: =IFERROR((H28-G28)/G28,0) -> 1.6823529 | K28: =E28*G28+(E28-IF(F28="500 Cashback",500,IF(F28="BOGOF",E28*50%,IF(F28="25% OFF",E28*25%,IF(F28="33% OFF",E28*33%,IF(F28="50% OFF",E28*50%,0))))))*H28 -> 825000 | L28: =VLOOKUP($B28,dim_stores!$A$1:$C$51,2,0) -> Coimbatore
... A39: 292ca5 | B39: STHYD-2 | C39: CAMP_DIW_01 | D39: P04 | E39: 290 | F39: 25% OFF | G39: 287 | H39: 220 | I39: =_xlfn.XLOOKUP($C39,dim_campaigns!$D$2:$D$3,dim_campaigns!$A$2:$A$3,"",0) -> Diwali | J39: =IFERROR((H39-G39)/G39,0) -> -0.23344948 | K39: =E39*G39+(E39-IF(F39="500 Cashback",500,IF(F39="BOGOF",E39*50%,IF(F39="25% OFF",E39*25%,IF(F39="33% OFF",E39*33%,IF(F39="50% OFF",E39*50%,0))))))*H39 -> 131080 | L39: =VLOOKUP($B39,dim_stores!$A$1:$C$51,2,0) -> Hyderabad
A40: 620715 | B40: STMYS-3 | C40: CAMP_SAN_01 | D40: P03 | E40: 200 | F40: BOGOF | G40: 340 | H40: 1485 | I40: =_xlfn.XLOOKUP($C40,dim_campaigns!$D$2:$D$3,dim_campaigns!$A$2:$A$3,"",0) -> Sankranti | J40: =IFERROR((H40-G40)/G40,0) -> 3.3676471 | K40: =E40*G40+(E40-IF(F40="500 Cashback",500,IF(F40="BOGOF",E40*50%,IF(F40="25% OFF",E40*25%,IF(F40="33% OFF",E40*33%,IF(F40="50% OFF",E40*50%,0))))))*H40 -> 216500 | L40: =VLOOKUP($B40,dim_stores!$A$1:$C$51,2,0) -> Mysuru
A41: 7e9777 | B41: STVJD-1 | C41: CAMP_DIW_01 | D41: P08 | E41: 1190 | F41: BOGOF | G41: 24 | H41: 82 | I41: =_xlfn.XLOOKUP($C41,dim_campaigns!$D$2:$D$3,dim_campaigns!$A$2:$A$3,"",0) -> Diwali | J41: =IFERROR((H41-G41)/G41,0) -> 2.4166667 | K41: =E41*G41+(E41-IF(F41="500 Cashback",500,IF(F41="BOGOF",E41*50%,IF(F41="25% OFF",E41*25%,IF(F41="33% OFF",E41*33%,IF(F41="50% OFF",E41*50%,0))))))*H41 -> 77350 | L41: =VLOOKUP($B41,dim_stores!$A$1:$C$51,2,0) -> Vijayawada
A42: 761785 | B42: STBLR-4 | C42: CAMP_SAN_01 | D42: P14 | E42: 1020 | F42: BOGOF | G42: 121 | H42: 474 | I42: =_xlfn.XLOOKUP($C42,dim_campaigns!$D$2:$D$3,dim_campaigns!$A$2:$A$3,"",0) -> Sankranti | J42: =IFERROR((H42-G42)/G42,0) -> 2.9173554 | K42: =E42*G42+(E42-IF(F42="500 Cashback",500,IF(F42="BOGOF",E42*50%,IF(F42="25% OFF",E42*25%,IF(F42="33% OFF",E42*33%,IF(F42="50% OFF",E42*50%,0))))))*H42 -> 365160 | L42: =VLOOKUP($B42,dim_stores!$A$1:$C$51,2,0) -> Bengaluru
A43: eb3bea | B43: STVSK-2 | C43: CAMP_SAN_01 | D43: P15 | E43: 3000 | F43: 500 Cashback | G43: 109 | H43: 238 | I43: =_xlfn.XLOOKUP($C43,dim_campaigns!$D$2:$D$3,dim_campaigns!$A$2:$A$3,"",0) -> Sankranti | J43: =IFERROR((H43-G43)/G43,0) -> 1.1834862 | K43: =E43*G43+(E43-IF(F43="500 Cashback",500,IF(F43="BOGOF",E43*50%,IF(F43="25% OFF",E43*25%,IF(F43="33% OFF",E43*33%,IF(F43="50% OFF",E43*50%,0))))))*H43 -> 922000 | L43: =VLOOKUP($B43,dim_stores!$A$1:$C$51,2,0) -> Visakhapatnam
A44: 276150 | B44: STCBE-3 | C44: CAMP_SAN_01 | D44: P07 | E44: 300 | F44: BOGOF | G44: 33 | H44: 128 | I44: =_xlfn.XLOOKUP($C44,dim_campaigns!$D$2:$D$3,dim_campaigns!$A$2:$A$3,"",0) -> Sankranti | J44: =IFERROR((H44-G44)/G44,0) -> 2.8787879 | K44: =E44*G44+(E44-IF(F44="500 Cashback",500,IF(F44="BOGOF",E44*50%,IF(F44="25% OFF",E44*25%,IF(F44="33% OFF",E44*33%,IF(F44="50% OFF",E44*50%,0))))))*H44 -> 29100 | L44: =VLOOKUP($B44,dim_stores!$A$1:$C$51,2,0) -> Coimbatore
A45: 3beb46 | B45: STMYS-2 | C45: CAMP_SAN_01 | D45: P13 | E45: 350 | F45: BOGOF | G45: 81 | H45: 208 | I45: =_xlfn.XLOOKUP($C45,dim_campaigns!$D$2:$D$3,dim_campaigns!$A$2:$A$3,"",0) -> Sankranti | J45: =IFERROR((H45-G45)/G45,0) -> 1.5679012 | K45: =E45*G45+(E45-IF(F45="500 Cashback",500,IF(F45="BOGOF",E45*50%,IF(F45="25% OFF",E45*25%,IF(F45="33% OFF",E45*33%,IF(F45="50% OFF",E45*50%,0))))))*H45 -> 64750 | L45: =VLOOKUP($B45,dim_stores!$A$1:$C$51,2,0) -> Mysuru
A46: 47af00 | B46: STVJD-1 | C46: CAMP_DIW_01 | D46: P03 | E46: 156 | F46: 25% OFF | G46: 183 | H46: 150 | I46: =_xlfn.XLOOKUP($C46,dim_campaigns!$D$2:$D$3,dim_campaigns!$A$2:$A$3,"",0) -> Diwali | J46: =IFERROR((H46-G46)/G46,0) -> -0.18032787 | K46: =E46*G46+(E46-IF(F46="500 Cashback",500,IF(F46="BOGOF",E46*50%,IF(F46="25% OFF",E46*25%,IF(F46="33% OFF",E46*33%,IF(F46="50% OFF",E46*50%,0))))))*H46 -> 46098 | L46: =VLOOKUP($B46,dim_stores!$A$1:$C$51,2,0) -> Vijayawada
A47: 627200 | B47: STCBE-4 | C47: CAMP_DIW_01 | D47: P14 | E47: 1020 | F47: BOGOF | G47: 36 | H47: 111 | I47: =_xlfn.XLOOKUP($C47,dim_campaigns!$D$2:$D$3,dim_campaigns!$A$2:$A$3,"",0) -> Diwali | J47: =IFERROR((H47-G47)/G47,0) -> 2.0833333 | K47: =E47*G47+(E47-IF(F47="500 Cashback",500,IF(F47="BOGOF",E47*50%,IF(F47="25% OFF",E47*25%,IF(F47="33% OFF",E47*33%,IF(F47="50% OFF",E47*50%,0))))))*H47 -> 93330 | L47: =VLOOKUP($B47,dim_stores!$A$1:$C$51,2,0) -> Coimbatore
A48: bc8315 | B48: STHYD-1 | C48: CAMP_DIW_01 | D48: P12 | E48: 62 | F48: 50% OFF | G48: 122 | H48: 135 | I48: =_xlfn.XLOOKUP($C48,dim_campaigns!$D$2:$D$3,dim_campaigns!$A$2:$A$3,"",0) -> Diwali | J48: =IFERROR((H48-G48)/G48,0) -> 0.10655738 | K48: =E48*G48+(E48-IF(F48="500 Cashback",500,IF(F48="BOGOF",E48*50%,IF(F48="25% OFF",E48*25%,IF(F48="33% OFF",E48*33%,IF(F48="50% OFF",E48*50%,0))))))*H48 -> 11749 | L48: =VLOOKUP($B48,dim_stores!$A$1:$C$51,2,0) -> Hyderabad
A49: 1f083a | B49: STVJD-0 | C49: CAMP_SAN_01 | D49: P06 | E49: 415 | F49: 25% OFF | G49: 16 | H49: 14 | I49: =_xlfn.XLOOKUP($C49,dim_campaigns!$D$2:$D$3,dim_campaigns!$A$2:$A$3,"",0) -> Sankranti | J49: =IFERROR((H49-G49)/G49,0) -> -0.125 | K49: =E49*G49+(E49-IF(F49="500 Cashback",500,IF(F49="BOGOF",E49*50%,IF(F49="25% OFF",E49*25%,IF(F49="33% OFF",E49*33%,IF(F49="50% OFF",E49*50%,0))))))*H49 -> 10997.5 | L49: =VLOOKUP($B49,dim_stores!$A$1:$C$51,2,0) -> Vijayawada
A50: c1e0b6 | B50: STCHE-6 | C50: CAMP_SAN_01 | D50: P01 | E50: 172 | F50: 33% OFF | G50: 273 | H50: 379 | I50: =_xlfn.XLOOKUP($C50,dim_campaigns!$D$2:$D$3,dim_campaigns!$A$2:$A$3,"",0) -> Sankranti | J50: =IFERROR((H50-G50)/G50,0) -> 0.38827839 | K50: =E50*G50+(E50-IF(F50="500 Cashback",500,IF(F50="BOGOF",E50*50%,IF(F50="25% OFF",E50*25%,IF(F50="33% OFF",E50*33%,IF(F50="50% OFF",E50*50%,0))))))*H50 -> 90631.96 | L50: =VLOOKUP($B50,dim_stores!$A$1:$C$51,2,0) -> Chennai
...

Sheet dim_stores
A1: store_id | B1: city | C1: Total Sales Amount
A2: STTRV-0 | B2: Trivandrum | C2: =SUMIF(fact_events!$B$2:$B$1501,A2,fact_events!$K$2:$K$1501) -> 4585941.4
A3: STMDU-3 | B3: Madurai | C3: =SUMIF(fact_events!$B$2:$B$1501,A3,fact_events!$K$2:$K$1501) -> 7484175.7
A4: STHYD-6 | B4: Hyderabad | C4: =SUMIF(fact_events!$B$2:$B$1501,A4,fact_events!$K$2:$K$1501) -> 8863318.2
A5: STVSK-1 | B5: Visakhapatnam | C5: =SUMIF(fact_events!$B$2:$B$1501,A5,fact_events!$K$2:$K$1501) -> 6619042.1
A6: STCBE-3 | B6: Coimbatore | C6: =SUMIF(fact_events!$B$2:$B$1501,A6,fact_events!$K$2:$K$1501) -> 6196168.4
A7: STBLR-8 | B7: Bengaluru | C7: =SUMIF(fact_events!$B$2:$B$1501,A7,fact_events!$K$2:$K$1501) -> 9480657.7
A8: STBLR-2 | B8: Bengaluru | C8: =SUMIF(fact_events!$B$2:$B$1501,A8,fact_events!$K$2:$K$1501) -> 8020512.8
A9: STCHE-7 | B9: Chennai | C9: =SUMIF(fact_events!$B$2:$B$1501,A9,fact_events!$K$2:$K$1501) -> 9854530.7
A10: STCBE-0 | B10: Coimbatore | C10: =SUMIF(fact_events!$B$2:$B$1501,A10,fact_events!$K$2:$K$1501) -> 7467733.7
A11: STVSK-0 | B11: Visakhapatnam | C11: =SUMIF(fact_events!$B$2:$B$1501,A11,fact_events!$K$2:$K$1501) -> 6210845.2
A12: STCHE-5 | B12: Chennai | C12: =SUMIF(fact_events!$B$2:$B$1501,A12,fact_events!$K$2:$K$1501) -> 9075445.7
A13: STHYD-5 | B13: Hyderabad | C13: =SUMIF(fact_events!$B$2:$B$1501,A13,fact_events!$K$2:$K$1501) -> 8576997.8
... A51: STMYS-1 | B51: Mysuru | C51: =SUMIF(fact_events!$B$2:$B$1501,A51,fact_events!$K$2:$K$1501) -> 10712670

Sheet dim_products
A1: product_code | B1: product_name | C1: category | D1: Total Quantity
A2: P01 | B2: Atliq_Masoor_Dal (1KG) | C2: Grocery & Staples | D2: =SUMIF(fact_events!$D$2:$D$1501,A2,fact_events!$G$2:$G$1501)+SUMIF(fact_events!$D$2:$D$1501,A2,fact_events!$H$2:$H$1501) -> 63381
A3: P02 | B3: Atliq_Sonamasuri_Rice (10KG) | C3: Grocery & Staples | D3: =SUMIF(fact_events!$D$2:$D$1501,A3,fact_events!$G$2:$G$1501)+SUMIF(fact_events!$D$2:$D$1501,A3,fact_events!$H$2:$H$1501) -> 90516
A4: P03 | B4: Atliq_Suflower_Oil (1L) | C4: Grocery & Staples | D4: =SUMIF(fact_events!$D$2:$D$1501,A4,fact_events!$G$2:$G$1501)+SUMIF(fact_events!$D$2:$D$1501,A4,fact_events!$H$2:$H$1501) -> 105787
A5: P04 | B5: Atliq_Farm_Chakki_Atta (1KG) | C5: Grocery & Staples | D5: =SUMIF(fact_events!$D$2:$D$1501,A5,fact_events!$G$2:$G$1501)+SUMIF(fact_events!$D$2:$D$1501,A5,fact_events!$H$2:$H$1501) -> 113630
A6: P05 | B6: Atliq_Scrub_Sponge_For_Dishwash | C6: Home Care | D6: =SUMIF(fact_events!$D$2:$D$1501,A6,fact_events!$G$2:$G$1501)+SUMIF(fact_events!$D$2:$D$1501,A6,fact_events!$H$2:$H$1501) -> 10747
A7: P06 | B7: Atliq_Fusion_Container_Set_of_3 | C7: Home Care | D7: =SUMIF(fact_events!$D$2:$D$1501,A7,fact_events!$G$2:$G$1501)+SUMIF(fact_events!$D$2:$D$1501,A7,fact_events!$H$2:$H$1501) -> 9679
A8: P09 | B8: Atliq_Body_Milk_Nourishing_Lotion (120ML) | C8: Personal Care | D8: =SUMIF(fact_events!$D$2:$D$1501,A8,fact_events!$G$2:$G$1501)+SUMIF(fact_events!$D$2:$D$1501,A8,fact_events!$H$2:$H$1501) -> 12454
A9: P10 | B9: Atliq_Cream_Beauty_Bathing_Soap (125GM) | C9: Personal Care | D9: =SUMIF(fact_events!$D$2:$D$1501,A9,fact_events!$G$2:$G$1501)+SUMIF(fact_events!$D$2:$D$1501,A9,fact_events!$H$2:$H$1501) -> 14077
A10: P13 | B10: Atliq_High_Glo_15W_LED_Bulb | C10: Home Appliances | D10: =SUMIF(fact_events!$D$2:$D$1501,A10,fact_events!$G$2:$G$1501)+SUMIF(fact_events!$D$2:$D$1501,A10,fact_events!$H$2:$H$1501) -> 38173
A11: P14 | B11: Atliq_waterproof_Immersion_Rod | C11: Home Appliances | D11: =SUMIF(fact_events!$D$2:$D$1501,A11,fact_events!$G$2:$G$1501)+SUMIF(fact_events!$D$2:$D$1501,A11,fact_events!$H$2:$H$1501) -> 30153
A12: P11 | B12: Atliq_Doodh_Kesar_Body_Lotion (200ML) | C12: Personal Care | D12: =SUMIF(fact_events!$D$2:$D$1501,A12,fact_events!$G$2:$G$1501)+SUMIF(fact_events!$D$2:$D$1501,A12,fact_events!$H$2:$H$1501) -> 12279
A13: P12 | B13: Atliq_Lime_Cool_Bathing_Bar (125GM) | C13: Personal Care | D13: =SUMIF(fact_events!$D$2:$D$1501,A13,fact_events!$G$2:$G$1501)+SUMIF(fact_events!$D$2:$D$1501,A13,fact_events!$H$2:$H$1501) -> 17998
... A16: P15 | B16: Atliq_Home_Essential_8_Product_Combo | C16: Combo1 | D16: =SUMIF(fact_events!$D$2:$D$1501,A16,fact_events!$G$2:$G$1501)+SUMIF(fact_events!$D$2:$D$1501,A16,fact_events!$H$2:$H$1501) -> 85479

Sheet dim_campaigns
A1: campaign_name | B1: start_date | C1: end_date | D1: campaign_id
A2: Diwali | B2: 45271 | C2: 18-11-2023 | D2: CAMP_DIW_01
A3: Sankranti | B3: 45566 | C3: 16-01-2024 | D3: CAMP_SAN_01
